<mujoco model="2d_slider">
    <actuator>
        <motor name="slide_x" joint="slider_x" gear="10" ctrllimited="true" ctrlrange="-1 1" />
        <motor name="slide_y" joint="slider_y" gear="10" ctrllimited="true" ctrlrange="-1 1" />
    </actuator>
    <asset>
        <texture name="grid" type="2d" builtin="checker" rgb1=".1 .2 .3" rgb2=".2 .3 .4" width="300" height="300" mark="edge" markrgb=".2 .3 .4"/>
        <material name="grid" texture="grid" texrepeat="1 1" texuniform="true" reflectance=".2"/>
        <material name="self" rgba=".7 .5 .3 1"/>
        <material name="self_default" rgba=".7 .5 .3 1"/>
        <material name="self_highlight" rgba="0 .5 .3 1"/>
        <material name="effector" rgba=".7 .4 .2 1"/>
        <material name="effector_default" rgba=".7 .4 .2 1"/>
        <material name="effector_highlight" rgba="0 .5 .3 1"/>
        <material name="decoration" rgba=".3 .5 .7 1"/>
        <material name="eye" rgba="0 .2 1 1"/>
        <material name="target" rgba=".6 .3 .3 1"/>
        <material name="target_default" rgba=".6 .3 .3 1"/>
        <material name="target_highlight" rgba=".6 .3 .3 .4"/>
        <material name="site" rgba=".5 .5 .5 .3"/>
        <material name="transparent" rgba=".5 .5 .5 .5"/>
    </asset>
    <worldbody>

        <body name="slider_base" pos="0 0 0">
            <joint name="slider_x" type="slide" limited="true" axis="1 0 0" range="-0.1 0.1" solreflimit=".08 1" damping="5e-4"/>
            <joint name="slider_y" type="slide" limited="true" axis="0 1 0" range="-1.0 0.1" solreflimit=".08 1" damping="5e-4"/>
            <body name="ft_sensor">
                <site name="ft_frame" pos="0 -0.05 0" size="0.01 0.01 0.01" rgba="1 0 0 0.5" type="sphere" group="0" />
                <geom type="box" size="0.2 0.05 0.1" mass="0.01" group="0"/>
                <geom type="box" size="0.2 0.05 0.1" material="decoration" group="1"/>
                <body name="slider_tip" pos="0 -0.15 0">
                    <geom name="slider_tip" type="box" size="0.2 0.1 0.1" mass="1.5" material="self" group="0"/>
                    <geom name="slider_tip_vis" type="box" size="0.2 0.1 0.1" mass="0.1" material="self" group="1"/>
                    <site rgba="0 1. 0 0.5" size="0.005" pos="0 -0.1 0" name="tip_site"/>

                </body>
            </body>
        </body>
    </worldbody>
    <sensor>
        <force name="force_ee" site="ft_frame"/>
        <torque name="torque_ee" site="ft_frame"/>
        <accelerometer name='acc_ee' site="ft_frame"/>
    </sensor>
</mujoco>
